Workbook

Sheet Dashboard
A1: Jet overflow charter business: dashboard
A2: Change the scenario on the Assumptions sheet (cell C3). All figures update.
A3: ="Scenario shown: "&Assumptions!$D$3 -> Scenario shown: Base
A5: Metric | C5: Value | D5: What it means
A6: Purchase price, Jet #1 | C6: =Assumptions!$F$7 -> 13500000
A7: Equity needed to launch | C7: ='Startup Budget'!C17 -> 3968625 | D7: Down payment + startup costs + reserve
A8: Aircraft loan | C8: ='Startup Budget'!C16 -> 10800000
A9: Mature-year EBITDA, one jet | C9: ='Unit Economics'!F25 -> 509050 | D9: Before debt
A10: Annual debt service, one jet | C10: =-'Unit Economics'!F29 -> 1204574.2
A11: Cash flow after debt, one jet | C11: ='Unit Economics'!F30 -> -695524.23 | D11: Negative = owners fund the gap
A12: Breakeven billable hours (EBITDA) | C12: ='Unit Economics'!F36 -> 425.09878
A13: Breakeven billable hours incl. debt | C13: ='Unit Economics'!F37 -> 838.9707 | D13: Key target for the management company
A14: Peak cumulative owner equity (10 yrs) | C14: =Exit!C20 -> 17667996 | D14: Total cash Henry and partners must fund
A15: Net exit proceeds | C15: =Exit!C15 -> 31694343
A16: Multiple on invested equity | C16: =Exit!C18 -> 1.7938844
A17: Equity IRR | C17: =Exit!C19 -> 0.094001978 | D17: Before owner tax effects
A18: Owned aircraft at exit | C18: =INDEX(Forecast!$C$11:$L$11,MATCH(Assumptions!$F$60,Forecast!$C$5:$L$5,0)) -> 3
A19: Third-party managed aircraft at exit | C19: =INDEX(Forecast!$C$16:$L$16,MATCH(Assumptions!$F$60,Forecast!$C$5:$L$5,0)) -> 12
A20: Revenue in exit year | C20: =INDEX(Forecast!$C$23:$L$23,MATCH(Assumptions!$F$60,Forecast!$C$5:$L$5,0)) -> 21202564
A21: EBITDA in exit year | C21: =INDEX(Forecast!$C$36:$L$36,MATCH(Assumptions!$F$60,Forecast!$C$5:$L$5,0)) -> 5580710.6
A23: Legend
A24: Blue text: input you can change
A25: Black text: formula
A26: Green text: link to another sheet
A27: Yellow fill: key lever
A28: All estimates must be verified with quotes from lenders, the management company, insurers and an aircraft broker.

Sheet Assumptions
A1: Assumptions: Citation Latitude overflow charter business
A2: Blue = input you can change. Yellow = key lever. Column F (Live) feeds the forecast based on the scenario selected in C3.
A3: Active scenario (1 = Downside, 2 = Base, 3 = Upside) | C3: 2 | D3: =INDEX({"Downside","Base","Upside"},$C$3) -> Base
A5: Assumption | B5: Unit | C5: Downside | D5: Base | E5: Upside | F5: Live | G5: Source / note
A6: Aircraft acquisition (per aircraft)
A7: Purchase price, used Citation Latitude (2016-2019) | B7: $ | C7: 15000000 | D7: 13500000 | E7: 12500000 | F7: =CHOOSE($C$3,C7,D7,E7) -> 13500000 | G7: AvBuyer/Aircraft Bluebook guide: 2020 Latitude ~$17.5M (May 2025), asking range $18.75-22.5M for newer units. Older 2016-2019 units assumed lower. VERIFY with a broker/JETNET before LOI.
A8: Annual change in price paid for later aircraft | B8: % | C8: 0 | D8: 0 | E8: 0 | F8: =CHOOSE($C$3,C8,D8,E8) -> 0 | G8: Assumes later purchases are similar-vintage aircraft at today's price. Adjust if the market moves.
A9: Pre-buy inspection (Textron service center) | B9: $ | C9: 85000 | D9: 75000 | E9: 60000 | F9: =CHOOSE($C$3,C9,D9,E9) -> 75000 | G9: Estimate; includes ferry to inspection facility and borescope.
A10: Closing legal, escrow, title, registration | B10: $ | C10: 60000 | D10: 50000 | E10: 40000 | F10: =CHOOSE($C$3,C10,D10,E10) -> 50000 | G10: Estimate.
A11: Part 135 onboarding, conformity, Wi-Fi/avionics updates | B11: $ | C11: 200000 | D11: 150000 | E11: 100000 | F11: =CHOOSE($C$3,C11,D11,E11) -> 150000 | G11: Adding aircraft to operator's certificate (conformity, manuals, OpSpecs), plus connectivity charter customers expect. Estimate.
A12: Cosmetic interior / paint refresh | B12: $ | C12: 350000 | D12: 250000 | E12: 150000 | F12: =CHOOSE($C$3,C12,D12,E12) -> 250000 | G12: Fractional customers expect fleet-standard cabins. Estimate.
A13: Initial crew training and hiring (per aircraft) | B13: $ | C13: 100000 | D13: 75000 | E13: 50000 | F13: =CHOOSE($C$3,C13,D13,E13) -> 75000 | G13: Type rating for new hires (CE-680A) and Part 135 initial. Estimate.
A14: Company formation, legal, accounting, insurance setup (once) | B14: $ | C14: 75000 | D14: 50000 | E14: 35000 | F14: =CHOOSE($C$3,C14,D14,E14) -> 50000 | G14: LLC formation, operating agreement, aviation counsel, CPA, insurance broker. Estimate.
A15: Financing
A16: Loan-to-value (debt share of purchase price) | B16: % | C16: 0.8 | D16: 0.8 | E16: 0.8 | F16: =CHOOSE($C$3,C16,D16,E16) -> 0.8 | G16: Henry: assume at least 80% debt. See 'Financing Scenarios' for 60-90%.
A17: Interest rate (fixed) | B17: % | C17: 0.08 | D17: 0.0725 | E17: 0.0675 | F17: =CHOOSE($C$3,C17,D17,E17) -> 0.0725 | G17: Advertised jet loan rates ~5.6-9% (Sep/Oct 2026 rate sheets); prime 7.00% (Oct 2026). flycraft.com/aircraft-financing/aircraft-loan-rates
A18: Amortization period | B18: years | C18: 15 | D18: 15 | E18: 20 | F18: =CHOOSE($C$3,C18,D18,E18) -> 15 | G18: Typical 10-20 yr amortization, often with a 5-7 yr balloon refinanced at the time. Model assumes refinance on same terms.
A19: Charter revenue (per owned aircraft)
A20: Billable revenue hours per aircraft at maturity | B20: hrs/yr | C20: 500 | D20: 600 | E20: 700 | F20: =CHOOSE($C$3,C20,D20,E20) -> 600 | G20: Includes billable repositioning. Dedicated fractional supplemental lift can run 800+ hrs; retail-only charter often 300-450.
A21: Months in revenue service in 2027 | B21: months | C21: 5 | D21: 6 | E21: 6 | F21: =CHOOSE($C$3,C21,D21,E21) -> 6 | G21: Henry: target revenue flying mid-2027.
A22: Utilization in first year of service (% of mature) | B22: % | C22: 0.5 | D22: 0.6 | E22: 0.7 | F22: =CHOOSE($C$3,C22,D22,E22) -> 0.6 | G22: Ramp while operator builds the aircraft into its overflow rotation.
A23: Utilization in second year (% of mature) | B23: % | C23: 0.8 | D23: 0.9 | E23: 1 | F23: =CHOOSE($C$3,C23,D23,E23) -> 0.9
A24: Share of hours flown as fractional / program overflow | B24: % | C24: 0.4 | D24: 0.5 | E24: 0.6 | F24: =CHOOSE($C$3,C24,D24,E24) -> 0.5 | G24: NetJets, Flexjet, jet card and membership programs. The rest is broker/retail charter.
A25: Wholesale rate, overflow / subcontract trips | B25: $/hr | C25: 6750 | D25: 7000 | E25: 7250 | F25: =CHOOSE($C$3,C25,D25,E25) -> 7000 | G25: Wholesale is below retail. NetJets' own midsize lift program retails $8,000-10,900/hr (SherpaReport). Estimate; get actual subcontract rates from the management company.
A26: Retail / broker charter rate | B26: $/hr | C26: 8000 | D26: 8500 | E26: 9000 | F26: =CHOOSE($C$3,C26,D26,E26) -> 8500 | G26: Excludes 7.5% federal excise tax (collected from the customer and remitted). Estimate.
A27: Annual charter rate growth | B27: % | C27: 0.02 | D27: 0.03 | E27: 0.035 | F27: =CHOOSE($C$3,C27,D27,E27) -> 0.03
A28: Unpaid positioning hours (% of billable) | B28: % | C28: 0.15 | D28: 0.1 | E28: 0.08 | F28: =CHOOSE($C$3,C28,D28,E28) -> 0.1 | G28: Denver base means some empty legs to the coasts. Estimate.
A29: Variable operating costs (per flight hour)
A30: Fuel burn | B30: gal/hr | C30: 285 | D30: 270 | E30: 260 | F30: =CHOOSE($C$3,C30,D30,E30) -> 270 | G30: Flycraft cites 315 gal/hr block (conservative); typical mission average lower.
A31: Jet-A price (contract/volume pricing) | B31: $/gal | C31: 7 | D31: 6.5 | E31: 6 | F31: =CHOOSE($C$3,C31,D31,E31) -> 6.5 | G31: Flycraft used $7.66/gal retail (Oct 2026). Contract fuel cards typically discount.
A32: Airframe maintenance and parts | B32: $/hr | C32: 850 | D32: 750 | E32: 650 | F32: =CHOOSE($C$3,C32,D32,E32) -> 750 | G32: Flycraft range $800-1,300/hr incl. unscheduled. Estimate.
A33: Engine program (2 x PW306D1, ESP) | B33: $/hr | C33: 700 | D33: 660 | E33: 620 | F33: =CHOOSE($C$3,C33,D33,E33) -> 660 | G33: Flycraft range $275-425 per engine per hour. Engines must be on program for resale value.
A34: APU program | B34: $/hr | C34: 100 | D34: 80 | E34: 70 | F34: =CHOOSE($C$3,C34,D34,E34) -> 80 | G34: Estimate.
A35: Crew travel, landing, handling fees (not rebilled) | B35: $/hr | C35: 500 | D35: 450 | E35: 400 | F35: =CHOOSE($C$3,C35,D35,E35) -> 450 | G35: Flycraft range $400-650/hr.
A36: Fixed operating costs (per owned aircraft, per year)
A37: Captains per aircraft | B37: # | C37: 2 | D37: 2 | E37: 2 | F37: =CHOOSE($C$3,C37,D37,E37) -> 2 | G37: Chief pilot (Henry's partner) is one of the captains.
A38: First officers per aircraft | B38: # | C38: 1 | D38: 1 | E38: 1 | F38: =CHOOSE($C$3,C38,D38,E38) -> 1 | G38: Plus contract pilots for peaks.
A39: Captain salary | B39: $ | C39: 190000 | D39: 175000 | E39: 165000 | F39: =CHOOSE($C$3,C39,D39,E39) -> 175000 | G39: Midsize Part 135 market. Estimate.
A40: First officer salary | B40: $ | C40: 125000 | D40: 115000 | E40: 105000 | F40: =CHOOSE($C$3,C40,D40,E40) -> 115000 | G40: Estimate.
A41: Benefits and payroll tax load | B41: % | C41: 0.28 | D41: 0.25 | E41: 0.22 | F41: =CHOOSE($C$3,C41,D41,E41) -> 0.25 | G41: Flycraft used 43% (corporate); charter typically lower.
...

Sheet Startup Budget
A1: Startup budget: first aircraft (Live scenario)
A2: Uses and sources of cash to get Jet #1 flying revenue trips.
A4: Uses of cash | C4: Amount | D4: Note
A5: Purchase price | C5: =Assumptions!$F$7 -> 13500000 | D5: Assumptions
A6: Pre-buy inspection | C6: =Assumptions!$F$9 -> 75000
A7: Closing legal, escrow, title, registration | C7: =Assumptions!$F$10 -> 50000
A8: Part 135 onboarding, conformity, Wi-Fi/avionics | C8: =Assumptions!$F$11 -> 150000
A9: Interior/paint refresh | C9: =Assumptions!$F$12 -> 250000
A10: Initial crew training and hiring | C10: =Assumptions!$F$13 -> 75000
A11: Company formation, legal, accounting, insurance setup | C11: =Assumptions!$F$14 -> 50000
A12: Cash reserve (operating) | C12: ='Unit Economics'!$F$38 -> 618625 | D12: Months of fixed cost per Assumptions
A13: Total uses | C13: =SUM(C5:C12) -> 14768625
A15: Sources of cash | C15: Amount | D15: Note
A16: Aircraft loan | C16: =Assumptions!$F$7*Assumptions!$F$16 -> 10800000 | D16: Senior secured loan at Live LTV
A17: Owner equity (Henry + partners) | C17: =C13-C16 -> 3968625
A18: Total sources | C18: =C16+C17 -> 14768625
A20: Equity as % of total uses | C20: =C17/C13 -> 0.26872001
A22: First full year operating budget (2028) | C22: Amount | D22: Note
A23: Charter revenue | C23: =Forecast!D20+Forecast!D21 -> 4310550 | D23: From Forecast, 2028 column
A24: Variable flight costs | C24: =-Forecast!D26 -> -2260674.9
A25: Crew | C25: =-Forecast!D27 -> -660487.5
A26: Training | C26: =-Forecast!D28 -> -108150
A27: Hangar, insurance, other fixed | C27: =-Forecast!D29 -> -289430
A28: Management fees | C28: =-Forecast!D30 -> -123600
A29: Manager's commission | C29: =-Forecast!D31 -> -431055
A30: Company G&A | C30: =-Forecast!D32 -> -92700
A31: EBITDA | C31: =Forecast!D36 -> 344452.6
A32: Debt service | C32: =-(Forecast!D39+Forecast!D40) -> -1204574.2
A33: Cash flow after debt service | C33: =Forecast!D41 -> -860121.63

Sheet Forecast
A1: 10-year forecast: company P&L, cash flow and equity (Live scenario)
A2: Annual, nominal dollars. Owned jets fly on the management company's certificate until the own-certificate year.
A3: ="Scenario: "&Assumptions!$D$3 -> Scenario: Base
A4: Line item | C4: 2027 | D4: 2028 | E4: 2029 | F4: 2030 | G4: 2031 | H4: 2032 | I4: 2033 | J4: 2034 | K4: 2035 | L4: 2036
A5: Year | C5: 2027 | D5: 2028 | E5: 2029 | F5: 2030 | G5: 2031 | H5: 2032 | I5: 2033 | J5: 2034 | K5: 2035 | L5: 2036
A6: Years from 2027 | C6: =C5-2027 -> 0 | D6: =D5-2027 -> 1 | E6: =E5-2027 -> 2 | F6: =F5-2027 -> 3 | G6: =G5-2027 -> 4 | H6: =H5-2027 -> 5 | I6: =I5-2027 -> 6 | J6: =J5-2027 -> 7 | ... L6: =L5-2027 -> 9
A7: On management company certificate? (1 = yes) | C7: =IF(C5<Assumptions!$F$54,1,0) -> 1 | D7: =IF(D5<Assumptions!$F$54,1,0) -> 1 | E7: =IF(E5<Assumptions!$F$54,1,0) -> 1 | F7: =IF(F5<Assumptions!$F$54,1,0) -> 0 | G7: =IF(G5<Assumptions!$F$54,1,0) -> 0 | H7: =IF(H5<Assumptions!$F$54,1,0) -> 0 | I7: =IF(I5<Assumptions!$F$54,1,0) -> 0 | J7: =IF(J5<Assumptions!$F$54,1,0) -> 0 | ... L7: =IF(L5<Assumptions!$F$54,1,0) -> 0
A8: Cost inflation index | C8: =(1+Assumptions!$F$51)^C6 -> 1 | D8: =(1+Assumptions!$F$51)^D6 -> 1.03 | E8: =(1+Assumptions!$F$51)^E6 -> 1.0609 | F8: =(1+Assumptions!$F$51)^F6 -> 1.092727 | G8: =(1+Assumptions!$F$51)^G6 -> 1.1255088 | H8: =(1+Assumptions!$F$51)^H6 -> 1.1592741 | I8: =(1+Assumptions!$F$51)^I6 -> 1.1940523 | J8: =(1+Assumptions!$F$51)^J6 -> 1.2298739 | ... L8: =(1+Assumptions!$F$51)^L6 -> 1.3047732
A10: Fleet and activity
A11: Owned aircraft (year end) | C11: ='Fleet Plan'!C9 -> 1 | D11: ='Fleet Plan'!D9 -> 1 | E11: ='Fleet Plan'!E9 -> 1 | F11: ='Fleet Plan'!F9 -> 2 | G11: ='Fleet Plan'!G9 -> 2 | H11: ='Fleet Plan'!H9 -> 2 | I11: ='Fleet Plan'!I9 -> 3 | J11: ='Fleet Plan'!J9 -> 3 | ... L11: ='Fleet Plan'!L9 -> 3
A12: Owned aircraft-years in service | C12: =C11*Assumptions!$F$21/12 -> 0.5 | D12: =(C11+D11)/2 -> 1 | E12: =(D11+E11)/2 -> 1 | F12: =(E11+F11)/2 -> 1.5 | G12: =(F11+G11)/2 -> 2 | H12: =(G11+H11)/2 -> 2 | I12: =(H11+I11)/2 -> 2.5 | J12: =(I11+J11)/2 -> 3 | K12: =(J11+K11)/2 -> 3 | L12: =(K11+L11)/2 -> 3
A13: Utilization factor | C13: =IF(C6=0,Assumptions!$F$22,IF(C6=1,Assumptions!$F$23,1)) -> 0.6 | D13: =IF(D6=0,Assumptions!$F$22,IF(D6=1,Assumptions!$F$23,1)) -> 0.9 | E13: =IF(E6=0,Assumptions!$F$22,IF(E6=1,Assumptions!$F$23,1)) -> 1 | F13: =IF(F6=0,Assumptions!$F$22,IF(F6=1,Assumptions!$F$23,1)) -> 1 | G13: =IF(G6=0,Assumptions!$F$22,IF(G6=1,Assumptions!$F$23,1)) -> 1 | H13: =IF(H6=0,Assumptions!$F$22,IF(H6=1,Assumptions!$F$23,1)) -> 1 | I13: =IF(I6=0,Assumptions!$F$22,IF(I6=1,Assumptions!$F$23,1)) -> 1 | J13: =IF(J6=0,Assumptions!$F$22,IF(J6=1,Assumptions!$F$23,1)) -> 1 | ... L13: =IF(L6=0,Assumptions!$F$22,IF(L6=1,Assumptions!$F$23,1)) -> 1
A14: Billable hours | C14: =C12*Assumptions!$F$20*C13 -> 180 | D14: =D12*Assumptions!$F$20*D13 -> 540 | E14: =E12*Assumptions!$F$20*E13 -> 600 | F14: =F12*Assumptions!$F$20*F13 -> 900 | G14: =G12*Assumptions!$F$20*G13 -> 1200 | H14: =H12*Assumptions!$F$20*H13 -> 1200 | I14: =I12*Assumptions!$F$20*I13 -> 1500 | J14: =J12*Assumptions!$F$20*J13 -> 1800 | ... L14: =L12*Assumptions!$F$20*L13 -> 1800
A15: Flight hours incl. positioning | C15: =C14*(1+Assumptions!$F$28) -> 198 | D15: =D14*(1+Assumptions!$F$28) -> 594 | E15: =E14*(1+Assumptions!$F$28) -> 660 | F15: =F14*(1+Assumptions!$F$28) -> 990 | G15: =G14*(1+Assumptions!$F$28) -> 1320 | H15: =H14*(1+Assumptions!$F$28) -> 1320 | I15: =I14*(1+Assumptions!$F$28) -> 1650 | J15: =J14*(1+Assumptions!$F$28) -> 1980 | ... L15: =L14*(1+Assumptions!$F$28) -> 1980
A16: Third-party managed aircraft (year end) | C16: ='Fleet Plan'!C15*(1-C7) -> 0 | D16: ='Fleet Plan'!D15*(1-D7) -> 0 | E16: ='Fleet Plan'!E15*(1-E7) -> 0 | F16: ='Fleet Plan'!F15*(1-F7) -> 1 | G16: ='Fleet Plan'!G15*(1-G7) -> 3 | H16: ='Fleet Plan'!H15*(1-H7) -> 5 | I16: ='Fleet Plan'!I15*(1-I7) -> 7 | J16: ='Fleet Plan'!J15*(1-J7) -> 9 | ... L16: ='Fleet Plan'!L15*(1-L7) -> 12
A17: Third-party managed aircraft (average) | C17: =0 -> 0 | D17: =(C16+D16)/2 -> 0 | E17: =(D16+E16)/2 -> 0 | F17: =(E16+F16)/2 -> 0.5 | G17: =(F16+G16)/2 -> 2 | H17: =(G16+H16)/2 -> 4 | I17: =(H16+I16)/2 -> 6 | J17: =(I16+J16)/2 -> 8 | K17: =(J16+K16)/2 -> 10 | L17: =(K16+L16)/2 -> 11.5
A19: Revenue
A20: Overflow / subcontract revenue | C20: =C14*Assumptions!$F$24*Assumptions!$F$25*(1+Assumptions!$F$27)^C6 -> 630000 | D20: =D14*Assumptions!$F$24*Assumptions!$F$25*(1+Assumptions!$F$27)^D6 -> 1946700 | E20: =E14*Assumptions!$F$24*Assumptions!$F$25*(1+Assumptions!$F$27)^E6 -> 2227890 | F20: =F14*Assumptions!$F$24*Assumptions!$F$25*(1+Assumptions!$F$27)^F6 -> 3442090 | G20: =G14*Assumptions!$F$24*Assumptions!$F$25*(1+Assumptions!$F$27)^G6 -> 4727137 | H20: =H14*Assumptions!$F$24*Assumptions!$F$25*(1+Assumptions!$F$27)^H6 -> 4868951.1 | I20: =I14*Assumptions!$F$24*Assumptions!$F$25*(1+Assumptions!$F$27)^I6 -> 6268774.6 | J20: =J14*Assumptions!$F$24*Assumptions!$F$25*(1+Assumptions!$F$27)^J6 -> 7748205.4 | ... L20: =L14*Assumptions!$F$24*Assumptions!$F$25*(1+Assumptions!$F$27)^L6 -> 8220071.1
A21: Broker / retail charter revenue | C21: =C14*(1-Assumptions!$F$24)*Assumptions!$F$26*(1+Assumptions!$F$27)^C6 -> 765000 | D21: =D14*(1-Assumptions!$F$24)*Assumptions!$F$26*(1+Assumptions!$F$27)^D6 -> 2363850 | E21: =E14*(1-Assumptions!$F$24)*Assumptions!$F$26*(1+Assumptions!$F$27)^E6 -> 2705295 | F21: =F14*(1-Assumptions!$F$24)*Assumptions!$F$26*(1+Assumptions!$F$27)^F6 -> 4179680.8 | G21: =G14*(1-Assumptions!$F$24)*Assumptions!$F$26*(1+Assumptions!$F$27)^G6 -> 5740094.9 | H21: =H14*(1-Assumptions!$F$24)*Assumptions!$F$26*(1+Assumptions!$F$27)^H6 -> 5912297.8 | I21: =I14*(1-Assumptions!$F$24)*Assumptions!$F$26*(1+Assumptions!$F$27)^I6 -> 7612083.4 | J21: =J14*(1-Assumptions!$F$24)*Assumptions!$F$26*(1+Assumptions!$F$27)^J6 -> 9408535.1 | ... L21: =L14*(1-Assumptions!$F$24)*Assumptions!$F$26*(1+Assumptions!$F$27)^L6 -> 9981514.9
A22: Third-party management margin (own certificate) | C22: =C17*Assumptions!$F$58*C8 -> 0 | D22: =D17*Assumptions!$F$58*D8 -> 0 | E22: =E17*Assumptions!$F$58*E8 -> 0 | F22: =F17*Assumptions!$F$58*F8 -> 109272.7 | G22: =G17*Assumptions!$F$58*G8 -> 450203.52 | H22: =H17*Assumptions!$F$58*H8 -> 927419.26 | I22: =I17*Assumptions!$F$58*I8 -> 1432862.8 | J22: =J17*Assumptions!$F$58*J8 -> 1967798.2 | ... L22: =L17*Assumptions!$F$58*L8 -> 3000978.3
A23: Total revenue | C23: =SUM(C20:C22) -> 1395000 | D23: =SUM(D20:D22) -> 4310550 | E23: =SUM(E20:E22) -> 4933185 | F23: =SUM(F20:F22) -> 7731043.5 | G23: =SUM(G20:G22) -> 10917435 | H23: =SUM(H20:H22) -> 11708668 | I23: =SUM(I20:I22) -> 15313721 | J23: =SUM(J20:J22) -> 19124539 | ... L23: =SUM(L20:L22) -> 21202564
A25: Operating costs
A26: Variable flight costs (fuel, maintenance, engines, APU, trip) | C26: =C15*(Assumptions!$F$30*Assumptions!$F$31+Assumptions!$F$32+Assumptions!$F$33+Assumptions!$F$34+Assumptions!$F$35)*C8 -> 731610 | D26: =D15*(Assumptions!$F$30*Assumptions!$F$31+Assumptions!$F$32+Assumptions!$F$33+Assumptions!$F$34+Assumptions!$F$35)*D8 -> 2260674.9 | E26: =E15*(Assumptions!$F$30*Assumptions!$F$31+Assumptions!$F$32+Assumptions!$F$33+Assumptions!$F$34+Assumptions!$F$35)*E8 -> 2587216.8 | F26: =F15*(Assumptions!$F$30*Assumptions!$F$31+Assumptions!$F$32+Assumptions!$F$33+Assumptions!$F$34+Assumptions!$F$35)*F8 -> 3997250 | G26: =G15*(Assumptions!$F$30*Assumptions!$F$31+Assumptions!$F$32+Assumptions!$F$33+Assumptions!$F$34+Assumptions!$F$35)*G8 -> 5489556.7 | H26: =H15*(Assumptions!$F$30*Assumptions!$F$31+Assumptions!$F$32+Assumptions!$F$33+Assumptions!$F$34+Assumptions!$F$35)*H8 -> 5654243.4 | I26: =I15*(Assumptions!$F$30*Assumptions!$F$31+Assumptions!$F$32+Assumptions!$F$33+Assumptions!$F$34+Assumptions!$F$35)*I8 -> 7279838.3 | J26: =J15*(Assumptions!$F$30*Assumptions!$F$31+Assumptions!$F$32+Assumptions!$F$33+Assumptions!$F$34+Assumptions!$F$35)*J8 -> 8997880.2 | ... L26: =L15*(Assumptions!$F$30*Assumptions!$F$31+Assumptions!$F$32+Assumptions!$F$33+Assumptions!$F$34+Assumptions!$F$35)*L8 -> 9545851.1
A27: Crew salaries, benefits, contract pilots | C27: =C12*((Assumptions!$F$37*Assumptions!$F$39+Assumptions!$F$38*Assumptions!$F$40)*(1+Assumptions!$F$41)+Assumptions!$F$42)*C8 -> 320625 | D27: =D12*((Assumptions!$F$37*Assumptions!$F$39+Assumptions!$F$38*Assumptions!$F$40)*(1+Assumptions!$F$41)+Assumptions!$F$42)*D8 -> 660487.5 | E27: =E12*((Assumptions!$F$37*Assumptions!$F$39+Assumptions!$F$38*Assumptions!$F$40)*(1+Assumptions!$F$41)+Assumptions!$F$42)*E8 -> 680302.12 | F27: =F12*((Assumptions!$F$37*Assumptions!$F$39+Assumptions!$F$38*Assumptions!$F$40)*(1+Assumptions!$F$41)+Assumptions!$F$42)*F8 -> 1051066.8 | G27: =G12*((Assumptions!$F$37*Assumptions!$F$39+Assumptions!$F$38*Assumptions!$F$40)*(1+Assumptions!$F$41)+Assumptions!$F$42)*G8 -> 1443465 | H27: =H12*((Assumptions!$F$37*Assumptions!$F$39+Assumptions!$F$38*Assumptions!$F$40)*(1+Assumptions!$F$41)+Assumptions!$F$42)*H8 -> 1486769 | I27: =I12*((Assumptions!$F$37*Assumptions!$F$39+Assumptions!$F$38*Assumptions!$F$40)*(1+Assumptions!$F$41)+Assumptions!$F$42)*I8 -> 1914215.1 | J27: =J12*((Assumptions!$F$37*Assumptions!$F$39+Assumptions!$F$38*Assumptions!$F$40)*(1+Assumptions!$F$41)+Assumptions!$F$42)*J8 -> 2365969.8 | ... L27: =L12*((Assumptions!$F$37*Assumptions!$F$39+Assumptions!$F$38*Assumptions!$F$40)*(1+Assumptions!$F$41)+Assumptions!$F$42)*L8 -> 2510057.4
A28: Recurrent training | C28: =C12*(Assumptions!$F$37+Assumptions!$F$38)*Assumptions!$F$43*C8 -> 52500 | D28: =D12*(Assumptions!$F$37+Assumptions!$F$38)*Assumptions!$F$43*D8 -> 108150 | E28: =E12*(Assumptions!$F$37+Assumptions!$F$38)*Assumptions!$F$43*E8 -> 111394.5 | F28: =F12*(Assumptions!$F$37+Assumptions!$F$38)*Assumptions!$F$43*F8 -> 172104.5 | G28: =G12*(Assumptions!$F$37+Assumptions!$F$38)*Assumptions!$F$43*G8 -> 236356.85 | H28: =H12*(Assumptions!$F$37+Assumptions!$F$38)*Assumptions!$F$43*H8 -> 243447.56 | I28: =I12*(Assumptions!$F$37+Assumptions!$F$38)*Assumptions!$F$43*I8 -> 313438.73 | J28: =J12*(Assumptions!$F$37+Assumptions!$F$38)*Assumptions!$F$43*J8 -> 387410.27 | ... L28: =L12*(Assumptions!$F$37+Assumptions!$F$38)*Assumptions!$F$43*L8 -> 411003.55
A29: Hangar, insurance, other fixed, contingency | C29: =C12*(Assumptions!$F$44+Assumptions!$F$45+Assumptions!$F$48+Assumptions!$F$49)*C8 -> 140500 | D29: =D12*(Assumptions!$F$44+Assumptions!$F$45+Assumptions!$F$48+Assumptions!$F$49)*D8 -> 289430 | E29: =E12*(Assumptions!$F$44+Assumptions!$F$45+Assumptions!$F$48+Assumptions!$F$49)*E8 -> 298112.9 | F29: =F12*(Assumptions!$F$44+Assumptions!$F$45+Assumptions!$F$48+Assumptions!$F$49)*F8 -> 460584.43 | G29: =G12*(Assumptions!$F$44+Assumptions!$F$45+Assumptions!$F$48+Assumptions!$F$49)*G8 -> 632535.95 | H29: =H12*(Assumptions!$F$44+Assumptions!$F$45+Assumptions!$F$48+Assumptions!$F$49)*H8 -> 651512.03 | I29: =I12*(Assumptions!$F$44+Assumptions!$F$45+Assumptions!$F$48+Assumptions!$F$49)*I8 -> 838821.74 | J29: =J12*(Assumptions!$F$44+Assumptions!$F$45+Assumptions!$F$48+Assumptions!$F$49)*J8 -> 1036783.7 | ... L29: =L12*(Assumptions!$F$44+Assumptions!$F$45+Assumptions!$F$48+Assumptions!$F$49)*L8 -> 1099923.8
A30: Management fees (on manager's certificate) | C30: =C7*C12*Assumptions!$F$46*12*C8 -> 60000 | D30: =D7*D12*Assumptions!$F$46*12*D8 -> 123600 | E30: =E7*E12*Assumptions!$F$46*12*E8 -> 127308 | F30: =F7*F12*Assumptions!$F$46*12*F8 -> 0 | G30: =G7*G12*Assumptions!$F$46*12*G8 -> 0 | H30: =H7*H12*Assumptions!$F$46*12*H8 -> 0 | I30: =I7*I12*Assumptions!$F$46*12*I8 -> 0 | J30: =J7*J12*Assumptions!$F$46*12*J8 -> 0 | ... L30: =L7*L12*Assumptions!$F$46*12*L8 -> 0
A31: Manager's charter commission | C31: =C7*(C20+C21)*Assumptions!$F$47 -> 139500 | D31: =D7*(D20+D21)*Assumptions!$F$47 -> 431055 | E31: =E7*(E20+E21)*Assumptions!$F$47 -> 493318.5 | F31: =F7*(F20+F21)*Assumptions!$F$47 -> 0 | G31: =G7*(G20+G21)*Assumptions!$F$47 -> 0 | H31: =H7*(H20+H21)*Assumptions!$F$47 -> 0 | I31: =I7*(I20+I21)*Assumptions!$F$47 -> 0 | J31: =J7*(J20+J21)*Assumptions!$F$47 -> 0 | ... L31: =L7*(L20+L21)*Assumptions!$F$47 -> 0
A32: Company G&A (before own certificate) | C32: =C7*Assumptions!$F$50*C8 -> 90000 | D32: =D7*Assumptions!$F$50*D8 -> 92700 | E32: =E7*Assumptions!$F$50*E8 -> 95481 | F32: =F7*Assumptions!$F$50*F8 -> 0 | G32: =G7*Assumptions!$F$50*G8 -> 0 | H32: =H7*Assumptions!$F$50*H8 -> 0 | I32: =I7*Assumptions!$F$50*I8 -> 0 | J32: =J7*Assumptions!$F$50*J8 -> 0 | ... L32: =L7*Assumptions!$F$50*L8 -> 0
A33: Own-certificate overhead | C33: =(1-C7)*(Assumptions!$F$56+Assumptions!$F$57*(C12+C17))*C8 -> 0 | D33: =(1-D7)*(Assumptions!$F$56+Assumptions!$F$57*(D12+D17))*D8 -> 0 | E33: =(1-E7)*(Assumptions!$F$56+Assumptions!$F$57*(E12+E17))*E8 -> 0 | F33: =(1-F7)*(Assumptions!$F$56+Assumptions!$F$57*(F12+F17))*F8 -> 1038090.7 | G33: =(1-G7)*(Assumptions!$F$56+Assumptions!$F$57*(G12+G17))*G8 -> 1181784.3 | H33: =(1-H7)*(Assumptions!$F$56+Assumptions!$F$57*(H12+H17))*H8 -> 1333165.2 | I33: =(1-I7)*(Assumptions!$F$56+Assumptions!$F$57*(I12+I17))*I8 -> 1522416.7 | J33: =(1-J7)*(Assumptions!$F$56+Assumptions!$F$57*(J12+J17))*J8 -> 1721823.4 | ... L33: =(1-L7)*(Assumptions!$F$56+Assumptions!$F$57*(L12+L17))*L8 -> 2055017.8
A34: Total operating costs | C34: =SUM(C26:C33) -> 1534735 | D34: =SUM(D26:D33) -> 3966097.4 | E34: =SUM(E26:E33) -> 4393133.9 | F34: =SUM(F26:F33) -> 6719096.4 | G34: =SUM(G26:G33) -> 8983698.8 | H34: =SUM(H26:H33) -> 9369137.1 | I34: =SUM(I26:I33) -> 11868731 | J34: =SUM(J26:J33) -> 14509867 | ... L34: =SUM(L26:L33) -> 15621854
A36: EBITDA | C36: =C23-C34 -> -139735 | D36: =D23-D34 -> 344452.6 | E36: =E23-E34 -> 540051.15 | F36: =F23-F34 -> 1011947.2 | G36: =G23-G34 -> 1933736.7 | H36: =H23-H34 -> 2339531 | I36: =I23-I34 -> 3444990.1 | J36: =J23-J34 -> 4614671.2 | ... L36: =L23-L34 -> 5580710.6
A37: EBITDA margin | C37: =IF(C23=0,0,C36/C23) -> -0.10016846 | D37: =IF(D23=0,0,D36/D23) -> 0.0799092 | E37: =IF(E23=0,0,E36/E23) -> 0.10947312 | F37: =IF(F23=0,0,F36/F23) -> 0.13089399 | G37: =IF(G23=0,0,G36/G23) -> 0.17712371 | H37: =IF(H23=0,0,H36/H23) -> 0.19981188 | I37: =IF(I23=0,0,I36/I23) -> 0.22496101 | J37: =IF(J23=0,0,J36/J23) -> 0.24129582 | ... L37: =IF(L23=0,0,L36/L23) -> 0.26320923
A38: One-time: own-certificate startup | C38: =IF(C5=Assumptions!$F$54-1,Assumptions!$F$55,0) -> 0 | D38: =IF(D5=Assumptions!$F$54-1,Assumptions!$F$55,0) -> 0 | E38: =IF(E5=Assumptions!$F$54-1,Assumptions!$F$55,0) -> 350000 | F38: =IF(F5=Assumptions!$F$54-1,Assumptions!$F$55,0) -> 0 | G38: =IF(G5=Assumptions!$F$54-1,Assumptions!$F$55,0) -> 0 | H38: =IF(H5=Assumptions!$F$54-1,Assumptions!$F$55,0) -> 0 | I38: =IF(I5=Assumptions!$F$54-1,Assumptions!$F$55,0) -> 0 | J38: =IF(J5=Assumptions!$F$54-1,Assumptions!$F$55,0) -> 0 | ... L38: =IF(L5=Assumptions!$F$54-1,Assumptions!$F$55,0) -> 0
A39: Interest | C39: ='Debt Schedule'!C92 -> 783000 | D39: ='Debt Schedule'!D92 -> 752435.87 | E39: ='Debt Schedule'!E92 -> 719655.84 | F39: ='Debt Schedule'!F92 -> 1467499.3 | G39: ='Debt Schedule'!G92 -> 1399229.7 | H39: ='Debt Schedule'!H92 -> 1326010.6 | I39: ='Debt Schedule'!I92 -> 2030483.1 | J39: ='Debt Schedule'!J92 -> 1915698.2 | ... L39: ='Debt Schedule'!L92 -> 1660559.4
A40: Principal repayment | C40: ='Debt Schedule'!C93 -> 421574.23 | D40: ='Debt Schedule'!D93 -> 452138.36 | E40: ='Debt Schedule'!E93 -> 484918.39 | F40: ='Debt Schedule'!F93 -> 941649.2 | G40: ='Debt Schedule'!G93 -> 1009918.8 | H40: ='Debt Schedule'!H93 -> 1083137.9 | I40: ='Debt Schedule'!I93 -> 1583239.6 | J40: ='Debt Schedule'!J93 -> 1698024.5 | ... L40: ='Debt Schedule'!L93 -> 1953163.3
A41: Cash flow after debt service | C41: =C36-C38-C39-C40 -> -1344309.2 | D41: =D36-D38-D39-D40 -> -860121.63 | E41: =E36-E38-E39-E40 -> -1014523.1 | F41: =F36-F38-F39-F40 -> -1397201.3 | G41: =G36-G38-G39-G40 -> -475411.77 | H41: =H36-H38-H39-H40 -> -69617.449 | I41: =I36-I38-I39-I40 -> -168732.56 | J41: =J36-J38-J39-J40 -> 1000948.5 | ... L41: =L36-L38-L39-L40 -> 1966987.9
A43: Aircraft purchases and owner equity
A44: Aircraft purchased | C44: =C11 -> 1 | D44: =D11-C11 -> 0 | E44: =E11-D11 -> 0 | F44: =F11-E11 -> 1 | G44: =G11-F11 -> 0 | H44: =H11-G11 -> 0 | I44: =I11-H11 -> 1 | J44: =J11-I11 -> 0 | K44: =K11-J11 -> 0 | L44: =L11-K11 -> 0
A45: Price per aircraft | C45: =Assumptions!$F$7*(1+Assumptions!$F$8)^C6 -> 13500000 | D45: =Assumptions!$F$7*(1+Assumptions!$F$8)^D6 -> 13500000 | E45: =Assumptions!$F$7*(1+Assumptions!$F$8)^E6 -> 13500000 | F45: =Assumptions!$F$7*(1+Assumptions!$F$8)^F6 -> 13500000 | G45: =Assumptions!$F$7*(1+Assumptions!$F$8)^G6 -> 13500000 | H45: =Assumptions!$F$7*(1+Assumptions!$F$8)^H6 -> 13500000 | I45: =Assumptions!$F$7*(1+Assumptions!$F$8)^I6 -> 13500000 | J45: =Assumptions!$F$7*(1+Assumptions!$F$8)^J6 -> 13500000 | ... L45: =Assumptions!$F$7*(1+Assumptions!$F$8)^L6 -> 13500000
...

Sheet Fleet Plan
A1: Fleet plan by scenario
A2: Aircraft counts at year end. Owned = financed Latitudes. Third-party = other owners' jets managed on your certificate (only counts once you hold one).
A4: Item | C4: 2027 | D4: 2028 | E4: 2029 | F4: 2030 | G4: 2031 | H4: 2032 | I4: 2033 | J4: 2034 | K4: 2035 | L4: 2036
A5: Owned aircraft (year end)
A6: Downside | C6: 1 | D6: 1 | E6: 1 | F6: 1 | G6: 1 | H6: 1 | I6: 1 | J6: 1 | K6: 1 | L6: 1
A7: Base | C7: 1 | D7: 1 | E7: 1 | F7: 2 | G7: 2 | H7: 2 | I7: 3 | J7: 3 | K7: 3 | L7: 3
A8: Upside | C8: 1 | D8: 1 | E8: 2 | F8: 2 | G8: 3 | H8: 3 | I8: 4 | J8: 4 | K8: 4 | L8: 4
A9: Live (selected scenario) | C9: =CHOOSE(Assumptions!$C$3,C6,C7,C8) -> 1 | D9: =CHOOSE(Assumptions!$C$3,D6,D7,D8) -> 1 | E9: =CHOOSE(Assumptions!$C$3,E6,E7,E8) -> 1 | F9: =CHOOSE(Assumptions!$C$3,F6,F7,F8) -> 2 | G9: =CHOOSE(Assumptions!$C$3,G6,G7,G8) -> 2 | H9: =CHOOSE(Assumptions!$C$3,H6,H7,H8) -> 2 | I9: =CHOOSE(Assumptions!$C$3,I6,I7,I8) -> 3 | J9: =CHOOSE(Assumptions!$C$3,J6,J7,J8) -> 3 | ... L9: =CHOOSE(Assumptions!$C$3,L6,L7,L8) -> 3
A11: Third-party managed aircraft (year end)
A12: Downside | C12: 0 | D12: 0 | E12: 0 | F12: 0 | G12: 0 | H12: 0 | I12: 0 | J12: 0 | K12: 0 | L12: 0
A13: Base | C13: 0 | D13: 0 | E13: 0 | F13: 1 | G13: 3 | H13: 5 | I13: 7 | J13: 9 | K13: 11 | L13: 12
A14: Upside | C14: 0 | D14: 0 | E14: 1 | F14: 3 | G14: 5 | H14: 7 | I14: 9 | J14: 11 | K14: 12 | L14: 14
A15: Live (selected scenario) | C15: =CHOOSE(Assumptions!$C$3,C12,C13,C14) -> 0 | D15: =CHOOSE(Assumptions!$C$3,D12,D13,D14) -> 0 | E15: =CHOOSE(Assumptions!$C$3,E12,E13,E14) -> 0 | F15: =CHOOSE(Assumptions!$C$3,F12,F13,F14) -> 1 | G15: =CHOOSE(Assumptions!$C$3,G12,G13,G14) -> 3 | H15: =CHOOSE(Assumptions!$C$3,H12,H13,H14) -> 5 | I15: =CHOOSE(Assumptions!$C$3,I12,I13,I14) -> 7 | J15: =CHOOSE(Assumptions!$C$3,J12,J13,J14) -> 9 | ... L15: =CHOOSE(Assumptions!$C$3,L12,L13,L14) -> 12

Sheet Unit Economics
A1: Unit economics: one Latitude, mature year, on management company certificate
A2: Today's dollars, no inflation. Shows whether a single financed jet carries itself.
A4: Line item | C4: Downside | D4: Base | E4: Upside | F4: Live
A5: Billable hours | C5: =Assumptions!$C$20 -> 500 | D5: =Assumptions!$D$20 -> 600 | E5: =Assumptions!$E$20 -> 700 | F5: =Assumptions!$F$20 -> 600
A6: Blended rate per billable hour | C6: =Assumptions!$C$24*Assumptions!$C$25+(1-Assumptions!$C$24)*Assumptions!$C$26 -> 7500 | D6: =Assumptions!$D$24*Assumptions!$D$25+(1-Assumptions!$D$24)*Assumptions!$D$26 -> 7750 | E6: =Assumptions!$E$24*Assumptions!$E$25+(1-Assumptions!$E$24)*Assumptions!$E$26 -> 7950 | F6: =Assumptions!$F$24*Assumptions!$F$25+(1-Assumptions!$F$24)*Assumptions!$F$26 -> 7750
A7: Charter revenue | C7: =C5*C6 -> 3750000 | D7: =D5*D6 -> 4650000 | E7: =E5*E6 -> 5565000 | F7: =F5*F6 -> 4650000
A8: Less manager's commission | C8: =-C7*Assumptions!$C$47 -> -450000 | D8: =-D7*Assumptions!$D$47 -> -465000 | E8: =-E7*Assumptions!$E$47 -> -445200 | F8: =-F7*Assumptions!$F$47 -> -465000
A9: Net charter revenue to owner | C9: =C7+C8 -> 3300000 | D9: =D7+D8 -> 4185000 | E9: =E7+E8 -> 5119800 | F9: =F7+F8 -> 4185000
A11: Flight hours incl. unpaid positioning | C11: =C5*(1+Assumptions!$C$28) -> 575 | D11: =D5*(1+Assumptions!$D$28) -> 660 | E11: =E5*(1+Assumptions!$E$28) -> 756 | F11: =F5*(1+Assumptions!$F$28) -> 660
A12: Variable cost per flight hour | C12: =Assumptions!$C$30*Assumptions!$C$31+Assumptions!$C$32+Assumptions!$C$33+Assumptions!$C$34+Assumptions!$C$35 -> 4145 | D12: =Assumptions!$D$30*Assumptions!$D$31+Assumptions!$D$32+Assumptions!$D$33+Assumptions!$D$34+Assumptions!$D$35 -> 3695 | E12: =Assumptions!$E$30*Assumptions!$E$31+Assumptions!$E$32+Assumptions!$E$33+Assumptions!$E$34+Assumptions!$E$35 -> 3300 | F12: =Assumptions!$F$30*Assumptions!$F$31+Assumptions!$F$32+Assumptions!$F$33+Assumptions!$F$34+Assumptions!$F$35 -> 3695
A13: Variable costs | C13: =-C11*C12 -> -2383375 | D13: =-D11*D12 -> -2438700 | E13: =-E11*E12 -> -2494800 | F13: =-F11*F12 -> -2438700
A15: Crew salaries and benefits | C15: =-((Assumptions!$C$37*Assumptions!$C$39+Assumptions!$C$38*Assumptions!$C$40)*(1+Assumptions!$C$41)+Assumptions!$C$42) -> -736400 | D15: =-((Assumptions!$D$37*Assumptions!$D$39+Assumptions!$D$38*Assumptions!$D$40)*(1+Assumptions!$D$41)+Assumptions!$D$42) -> -641250 | E15: =-((Assumptions!$E$37*Assumptions!$E$39+Assumptions!$E$38*Assumptions!$E$40)*(1+Assumptions!$E$41)+Assumptions!$E$42) -> -570700 | F15: =-((Assumptions!$F$37*Assumptions!$F$39+Assumptions!$F$38*Assumptions!$F$40)*(1+Assumptions!$F$41)+Assumptions!$F$42) -> -641250
A16: Recurrent training | C16: =-(Assumptions!$C$37+Assumptions!$C$38)*Assumptions!$C$43 -> -120000 | D16: =-(Assumptions!$D$37+Assumptions!$D$38)*Assumptions!$D$43 -> -105000 | E16: =-(Assumptions!$E$37+Assumptions!$E$38)*Assumptions!$E$43 -> -90000 | F16: =-(Assumptions!$F$37+Assumptions!$F$38)*Assumptions!$F$43 -> -105000
A17: Hangar | C17: =-Assumptions!$C$44 -> -84000 | D17: =-Assumptions!$D$44 -> -66000 | E17: =-Assumptions!$E$44 -> -54000 | F17: =-Assumptions!$F$44 -> -66000
A18: Insurance | C18: =-Assumptions!$C$45 -> -110000 | D18: =-Assumptions!$D$45 -> -85000 | E18: =-Assumptions!$E$45 -> -70000 | F18: =-Assumptions!$F$45 -> -85000
A19: Management fee | C19: =-Assumptions!$C$46*12 -> -132000 | D19: =-Assumptions!$D$46*12 -> -120000 | E19: =-Assumptions!$E$46*12 -> -102000 | F19: =-Assumptions!$F$46*12 -> -120000
A20: Other fixed | C20: =-Assumptions!$C$48 -> -100000 | D20: =-Assumptions!$D$48 -> -80000 | E20: =-Assumptions!$E$48 -> -65000 | F20: =-Assumptions!$F$48 -> -80000
A21: Contingency | C21: =-Assumptions!$C$49 -> -75000 | D21: =-Assumptions!$D$49 -> -50000 | E21: =-Assumptions!$E$49 -> -35000 | F21: =-Assumptions!$F$49 -> -50000
A22: Company G&A | C22: =-Assumptions!$C$50 -> -110000 | D22: =-Assumptions!$D$50 -> -90000 | E22: =-Assumptions!$E$50 -> -75000 | F22: =-Assumptions!$F$50 -> -90000
A23: Total fixed costs | C23: =SUM(C15:C22) -> -1467400 | D23: =SUM(D15:D22) -> -1237250 | E23: =SUM(E15:E22) -> -1061700 | F23: =SUM(F15:F22) -> -1237250
A25: EBITDA (operating cash flow before debt) | C25: =C9+C13+C23 -> -550775 | D25: =D9+D13+D23 -> 509050 | E25: =E9+E13+E23 -> 1563300 | F25: =F9+F13+F23 -> 509050
A26: EBITDA margin | C26: =IF(C7=0,0,C25/C7) -> -0.14687333 | D26: =IF(D7=0,0,D25/D7) -> 0.10947312 | E26: =IF(E7=0,0,E25/E7) -> 0.28091644 | F26: =IF(F7=0,0,F25/F7) -> 0.10947312
A28: Loan amount | C28: =Assumptions!$C$7*Assumptions!$C$16 -> 12000000 | D28: =Assumptions!$D$7*Assumptions!$D$16 -> 10800000 | E28: =Assumptions!$E$7*Assumptions!$E$16 -> 10000000 | F28: =Assumptions!$F$7*Assumptions!$F$16 -> 10800000
A29: Annual debt service | C29: =-PMT(Assumptions!$C$17,Assumptions!$C$18,-C28) -> -1401954.5 | D29: =-PMT(Assumptions!$D$17,Assumptions!$D$18,-D28) -> -1204574.2 | E29: =-PMT(Assumptions!$E$17,Assumptions!$E$18,-E28) -> -925666.96 | F29: =-PMT(Assumptions!$F$17,Assumptions!$F$18,-F28) -> -1204574.2
A30: Cash flow after debt service | C30: =C25+C29 -> -1952729.5 | D30: =D25+D29 -> -695524.23 | E30: =E25+E29 -> 637633.04 | F30: =F25+F29 -> -695524.23
A31: Of which: first-year interest | C31: =-C28*Assumptions!$C$17 -> -960000 | D31: =-D28*Assumptions!$D$17 -> -783000 | E31: =-E28*Assumptions!$E$17 -> -675000 | F31: =-F28*Assumptions!$F$17 -> -783000
A32: First-year decline in aircraft value | C32: =-Assumptions!$C$7*Assumptions!$C$63 -> -1050000 | D32: =-Assumptions!$D$7*Assumptions!$D$63 -> -675000 | E32: =-Assumptions!$E$7*Assumptions!$E$63 -> -437500 | F32: =-Assumptions!$F$7*Assumptions!$F$63 -> -675000
A33: Economic profit (EBITDA - interest - value decline) | C33: =C25+C31+C32 -> -2560775 | D33: =D25+D31+D32 -> -948950 | E33: =E25+E31+E32 -> 450800 | F33: =F25+F31+F32 -> -948950
A35: Contribution per billable hour | C35: =C6*(1-Assumptions!$C$47)-C12*(1+Assumptions!$C$28) -> 1833.25 | D35: =D6*(1-Assumptions!$D$47)-D12*(1+Assumptions!$D$28) -> 2910.5 | E35: =E6*(1-Assumptions!$E$47)-E12*(1+Assumptions!$E$28) -> 3750 | F35: =F6*(1-Assumptions!$F$47)-F12*(1+Assumptions!$F$28) -> 2910.5
A36: Breakeven billable hours (EBITDA = 0) | C36: =IF(C35<=0,0,-C23/C35) -> 800.43638 | D36: =IF(D35<=0,0,-D23/D35) -> 425.09878 | E36: =IF(E35<=0,0,-E23/E35) -> 283.12 | F36: =IF(F35<=0,0,-F23/F35) -> 425.09878
A37: Breakeven billable hours incl. debt service | C37: =IF(C35<=0,0,-(C23+C29)/C35) -> 1565.1736 | D37: =IF(D35<=0,0,-(D23+D29)/D35) -> 838.9707 | E37: =IF(E35<=0,0,-(E23+E29)/E35) -> 529.96452 | F37: =IF(F35<=0,0,-(F23+F29)/F35) -> 838.9707
A38: Cash reserve to hold | C38: =-C23/12*Assumptions!$C$52 -> 733700 | D38: =-D23/12*Assumptions!$D$52 -> 618625 | E38: =-E23/12*Assumptions!$E$52 -> 442375 | F38: =-F23/12*Assumptions!$F$52 -> 618625
A40: Sensitivity: Live scenario, cash flow after debt service by billable hours
A41: Billable hours | C41: EBITDA | D41: Debt service | E41: Cash after debt | F41: Per-hour margin
A42: 300 | C42: =A42*$F$35+$F$23 -> -364100 | D42: =$F$29 -> -1204574.2 | E42: =C42+D42 -> -1568674.2 | F42: =IF(A42=0,0,E42/A42) -> -5228.9141
A43: 400 | C43: =A43*$F$35+$F$23 -> -73050 | D43: =$F$29 -> -1204574.2 | E43: =C43+D43 -> -1277624.2 | F43: =IF(A43=0,0,E43/A43) -> -3194.0606
A44: 500 | C44: =A44*$F$35+$F$23 -> 218000 | D44: =$F$29 -> -1204574.2 | E44: =C44+D44 -> -986574.23 | F44: =IF(A44=0,0,E44/A44) -> -1973.1485
A45: 600 | C45: =A45*$F$35+$F$23 -> 509050 | D45: =$F$29 -> -1204574.2 | E45: =C45+D45 -> -695524.23 | F45: =IF(A45=0,0,E45/A45) -> -1159.207
A46: 700 | C46: =A46*$F$35+$F$23 -> 800100 | D46: =$F$29 -> -1204574.2 | E46: =C46+D46 -> -404474.23 | F46: =IF(A46=0,0,E46/A46) -> -577.82033
A47: 800 | C47: =A47*$F$35+$F$23 -> 1091150 | D47: =$F$29 -> -1204574.2 | E47: =C47+D47 -> -113424.23 | F47: =IF(A47=0,0,E47/A47) -> -141.78029
...

Sheet Financing Scenarios
A1: Financing scenarios: first aircraft, Live scenario
A2: How leverage changes cash needed and monthly cash flow. Change the LTV row (blue) to test other structures.
C4: Scenario 1 | D4: Scenario 2 | E4: Scenario 3 | F4: Scenario 4 | G4: Scenario 5 | H4: Scenario 6
A5: Loan-to-value | C5: 0.6 | D5: 0.7 | E5: 0.75 | F5: 0.8 | G5: 0.85 | H5: 0.9
A6: Purchase price | C6: =Assumptions!$F$7 -> 13500000 | D6: =Assumptions!$F$7 -> 13500000 | E6: =Assumptions!$F$7 -> 13500000 | F6: =Assumptions!$F$7 -> 13500000 | G6: =Assumptions!$F$7 -> 13500000 | H6: =Assumptions!$F$7 -> 13500000
A7: Loan | C7: =C6*C5 -> 8100000 | D7: =D6*D5 -> 9450000 | E7: =E6*E5 -> 10125000 | F7: =F6*F5 -> 10800000 | G7: =G6*G5 -> 11475000 | H7: =H6*H5 -> 12150000
A8: Down payment | C8: =C6-C7 -> 5400000 | D8: =D6-D7 -> 4050000 | E8: =E6-E7 -> 3375000 | F8: =F6-F7 -> 2700000 | G8: =G6-G7 -> 2025000 | H8: =H6-H7 -> 1350000
A9: Acquisition, onboarding and setup costs | C9: =Assumptions!$F$9+Assumptions!$F$10+Assumptions!$F$11+Assumptions!$F$12+Assumptions!$F$13+Assumptions!$F$14 -> 650000 | D9: =Assumptions!$F$9+Assumptions!$F$10+Assumptions!$F$11+Assumptions!$F$12+Assumptions!$F$13+Assumptions!$F$14 -> 650000 | E9: =Assumptions!$F$9+Assumptions!$F$10+Assumptions!$F$11+Assumptions!$F$12+Assumptions!$F$13+Assumptions!$F$14 -> 650000 | F9: =Assumptions!$F$9+Assumptions!$F$10+Assumptions!$F$11+Assumptions!$F$12+Assumptions!$F$13+Assumptions!$F$14 -> 650000 | G9: =Assumptions!$F$9+Assumptions!$F$10+Assumptions!$F$11+Assumptions!$F$12+Assumptions!$F$13+Assumptions!$F$14 -> 650000 | H9: =Assumptions!$F$9+Assumptions!$F$10+Assumptions!$F$11+Assumptions!$F$12+Assumptions!$F$13+Assumptions!$F$14 -> 650000
A10: Cash reserve | C10: ='Unit Economics'!$F$38 -> 618625 | D10: ='Unit Economics'!$F$38 -> 618625 | E10: ='Unit Economics'!$F$38 -> 618625 | F10: ='Unit Economics'!$F$38 -> 618625 | G10: ='Unit Economics'!$F$38 -> 618625 | H10: ='Unit Economics'!$F$38 -> 618625
A11: Total equity needed to launch | C11: =SUM(C8:C10) -> 6668625 | D11: =SUM(D8:D10) -> 5318625 | E11: =SUM(E8:E10) -> 4643625 | F11: =SUM(F8:F10) -> 3968625 | G11: =SUM(G8:G10) -> 3293625 | H11: =SUM(H8:H10) -> 2618625
A13: Annual debt service | C13: =PMT(Assumptions!$F$17,Assumptions!$F$18,-C7) -> 903430.67 | D13: =PMT(Assumptions!$F$17,Assumptions!$F$18,-D7) -> 1054002.5 | E13: =PMT(Assumptions!$F$17,Assumptions!$F$18,-E7) -> 1129288.3 | F13: =PMT(Assumptions!$F$17,Assumptions!$F$18,-F7) -> 1204574.2 | G13: =PMT(Assumptions!$F$17,Assumptions!$F$18,-G7) -> 1279860.1 | H13: =PMT(Assumptions!$F$17,Assumptions!$F$18,-H7) -> 1355146
A14: Monthly loan payment | C14: =C13/12 -> 75285.889 | D14: =D13/12 -> 87833.538 | E14: =E13/12 -> 94107.362 | F14: =F13/12 -> 100381.19 | G14: =G13/12 -> 106655.01 | H14: =H13/12 -> 112928.83
A15: Mature-year EBITDA (Unit Economics, Live) | C15: ='Unit Economics'!$F$25 -> 509050 | D15: ='Unit Economics'!$F$25 -> 509050 | E15: ='Unit Economics'!$F$25 -> 509050 | F15: ='Unit Economics'!$F$25 -> 509050 | G15: ='Unit Economics'!$F$25 -> 509050 | H15: ='Unit Economics'!$F$25 -> 509050
A16: Cash flow after debt service | C16: =C15-C13 -> -394380.67 | D16: =D15-D13 -> -544952.45 | E16: =E15-E13 -> -620238.34 | F16: =F15-F13 -> -695524.23 | G16: =G15-G13 -> -770810.12 | H16: =H15-H13 -> -846096.01
A17: Debt service coverage (EBITDA / debt service) | C17: =IF(C13=0,0,C15/C13) -> 0.56346327 | D17: =IF(D13=0,0,D15/D13) -> 0.48296852 | E17: =IF(E13=0,0,E15/E13) -> 0.45077062 | F17: =IF(F13=0,0,F15/F13) -> 0.42259745 | G17: =IF(G13=0,0,G15/G13) -> 0.39773878 | H17: =IF(H13=0,0,H15/H13) -> 0.37564218
A18: Cash-on-cash return | C18: =IF(C11=0,0,C16/C11) -> -0.059139729 | D18: =IF(D11=0,0,D16/D11) -> -0.10246115 | E18: =IF(E11=0,0,E16/E11) -> -0.13356771 | F18: =IF(F11=0,0,F16/F11) -> -0.17525572 | G18: =IF(G11=0,0,G16/G11) -> -0.23403093 | H18: =IF(H11=0,0,H16/H11) -> -0.32310698
A19: Breakeven billable hours incl. debt service | C19: =IF('Unit Economics'!$F$35<=0,0,(-'Unit Economics'!$F$23+C13)/'Unit Economics'!$F$35) -> 735.50272 | D19: =IF('Unit Economics'!$F$35<=0,0,(-'Unit Economics'!$F$23+D13)/'Unit Economics'!$F$35) -> 787.23671 | E19: =IF('Unit Economics'!$F$35<=0,0,(-'Unit Economics'!$F$23+E13)/'Unit Economics'!$F$35) -> 813.10371 | F19: =IF('Unit Economics'!$F$35<=0,0,(-'Unit Economics'!$F$23+F13)/'Unit Economics'!$F$35) -> 838.9707 | G19: =IF('Unit Economics'!$F$35<=0,0,(-'Unit Economics'!$F$23+G13)/'Unit Economics'!$F$35) -> 864.8377 | H19: =IF('Unit Economics'!$F$35<=0,0,(-'Unit Economics'!$F$23+H13)/'Unit Economics'!$F$35) -> 890.70469
A21: Lender reality check
A22: Credit-based jet loans typically need 15-20% down (80-85% LTV); asset-based loans 30-40% down (AOPA via flycraft.com).
A23: 85-90% leverage usually means a personal guarantee, strong outside liquidity, or a second-lien / seller note on top of the senior loan.
A24: Lenders want DSCR of about 1.25x on the business alone, or will underwrite Henry's personal income and liquidity instead.
A26: Cash flow after debt service: billable hours (rows) by LTV (columns)
A27: Billable hours | C27: =C5 -> 0.6 | D27: =D5 -> 0.7 | E27: =E5 -> 0.75 | F27: =F5 -> 0.8 | G27: =G5 -> 0.85 | H27: =H5 -> 0.9
A28: 400 | C28: =$A28*'Unit Economics'!$F$35+'Unit Economics'!$F$23-C$13 -> -976480.67 | D28: =$A28*'Unit Economics'!$F$35+'Unit Economics'!$F$23-D$13 -> -1127052.5 | E28: =$A28*'Unit Economics'!$F$35+'Unit Economics'!$F$23-E$13 -> -1202338.3 | F28: =$A28*'Unit Economics'!$F$35+'Unit Economics'!$F$23-F$13 -> -1277624.2 | G28: =$A28*'Unit Economics'!$F$35+'Unit Economics'!$F$23-G$13 -> -1352910.1 | H28: =$A28*'Unit Economics'!$F$35+'Unit Economics'!$F$23-H$13 -> -1428196
A29: 500 | C29: =$A29*'Unit Economics'!$F$35+'Unit Economics'!$F$23-C$13 -> -685430.67 | D29: =$A29*'Unit Economics'!$F$35+'Unit Economics'!$F$23-D$13 -> -836002.45 | E29: =$A29*'Unit Economics'!$F$35+'Unit Economics'!$F$23-E$13 -> -911288.34 | F29: =$A29*'Unit Economics'!$F$35+'Unit Economics'!$F$23-F$13 -> -986574.23 | G29: =$A29*'Unit Economics'!$F$35+'Unit Economics'!$F$23-G$13 -> -1061860.1 | H29: =$A29*'Unit Economics'!$F$35+'Unit Economics'!$F$23-H$13 -> -1137146
A30: 600 | C30: =$A30*'Unit Economics'!$F$35+'Unit Economics'!$F$23-C$13 -> -394380.67 | D30: =$A30*'Unit Economics'!$F$35+'Unit Economics'!$F$23-D$13 -> -544952.45 | E30: =$A30*'Unit Economics'!$F$35+'Unit Economics'!$F$23-E$13 -> -620238.34 | F30: =$A30*'Unit Economics'!$F$35+'Unit Economics'!$F$23-F$13 -> -695524.23 | G30: =$A30*'Unit Economics'!$F$35+'Unit Economics'!$F$23-G$13 -> -770810.12 | H30: =$A30*'Unit Economics'!$F$35+'Unit Economics'!$F$23-H$13 -> -846096.01
A31: 700 | C31: =$A31*'Unit Economics'!$F$35+'Unit Economics'!$F$23-C$13 -> -103330.67 | D31: =$A31*'Unit Economics'!$F$35+'Unit Economics'!$F$23-D$13 -> -253902.45 | E31: =$A31*'Unit Economics'!$F$35+'Unit Economics'!$F$23-E$13 -> -329188.34 | F31: =$A31*'Unit Economics'!$F$35+'Unit Economics'!$F$23-F$13 -> -404474.23 | G31: =$A31*'Unit Economics'!$F$35+'Unit Economics'!$F$23-G$13 -> -479760.12 | H31: =$A31*'Unit Economics'!$F$35+'Unit Economics'!$F$23-H$13 -> -555046.01
A32: 800 | C32: =$A32*'Unit Economics'!$F$35+'Unit Economics'!$F$23-C$13 -> 187719.33 | D32: =$A32*'Unit Economics'!$F$35+'Unit Economics'!$F$23-D$13 -> 37147.549 | E32: =$A32*'Unit Economics'!$F$35+'Unit Economics'!$F$23-E$13 -> -38138.34 | F32: =$A32*'Unit Economics'!$F$35+'Unit Economics'!$F$23-F$13 -> -113424.23 | G32: =$A32*'Unit Economics'!$F$35+'Unit Economics'!$F$23-G$13 -> -188710.12 | H32: =$A32*'Unit Economics'!$F$35+'Unit Economics'!$F$23-H$13 -> -263996.01
A33: 900 | C33: =$A33*'Unit Economics'!$F$35+'Unit Economics'!$F$23-C$13 -> 478769.33 | D33: =$A33*'Unit Economics'!$F$35+'Unit Economics'!$F$23-D$13 -> 328197.55 | E33: =$A33*'Unit Economics'!$F$35+'Unit Economics'!$F$23-E$13 -> 252911.66 | F33: =$A33*'Unit Economics'!$F$35+'Unit Economics'!$F$23-F$13 -> 177625.77 | G33: =$A33*'Unit Economics'!$F$35+'Unit Economics'!$F$23-G$13 -> 102339.88 | H33: =$A33*'Unit Economics'!$F$35+'Unit Economics'!$F$23-H$13 -> 27053.992

Sheet Debt Schedule
A1: Debt and aircraft value schedule by owned aircraft
A2: Each owned aircraft gets its own loan at the Live LTV and rate. Payments start in the purchase year (conservative).
A4: Item | C4: 2027 | D4: 2028 | E4: 2029 | F4: 2030 | G4: 2031 | H4: 2032 | I4: 2033 | J4: 2034 | K4: 2035 | L4: 2036
A5: Year | C5: 2027 | D5: 2028 | E5: 2029 | F5: 2030 | G5: 2031 | H5: 2032 | I5: 2033 | J5: 2034 | K5: 2035 | L5: 2036
A7: Aircraft #1
A8: Purchase year | B8: =2027+COUNTIF('Fleet Plan'!$C$9:$L$9,"<1") -> 2027
A9: Price paid | B9: =IF($B$8>2036,0,Assumptions!$F$7*(1+Assumptions!$F$8)^($B$8-2027)) -> 13500000
A10: Loan | B10: =$B$9*Assumptions!$F$16 -> 10800000
A11: Annual payment | B11: =IF($B$10=0,0,PMT(Assumptions!$F$17,Assumptions!$F$18,-$B$10)) -> 1204574.2
A12: Beginning balance | C12: =IF(C$5=$B$8,$B$10,IF(C$5>$B$8,0,0)) -> 10800000 | D12: =IF(D$5=$B$8,$B$10,IF(D$5>$B$8,C16,0)) -> 10378426 | E12: =IF(E$5=$B$8,$B$10,IF(E$5>$B$8,D16,0)) -> 9926287.4 | F12: =IF(F$5=$B$8,$B$10,IF(F$5>$B$8,E16,0)) -> 9441369 | G12: =IF(G$5=$B$8,$B$10,IF(G$5>$B$8,F16,0)) -> 8921294 | H12: =IF(H$5=$B$8,$B$10,IF(H$5>$B$8,G16,0)) -> 8363513.6 | I12: =IF(I$5=$B$8,$B$10,IF(I$5>$B$8,H16,0)) -> 7765294.1 | J12: =IF(J$5=$B$8,$B$10,IF(J$5>$B$8,I16,0)) -> 7123703.7 | K12: =IF(K$5=$B$8,$B$10,IF(K$5>$B$8,J16,0)) -> 6435598 | L12: =IF(L$5=$B$8,$B$10,IF(L$5>$B$8,K16,0)) -> 5697604.7
A13: Interest | C13: =C12*Assumptions!$F$17 -> 783000 | D13: =D12*Assumptions!$F$17 -> 752435.87 | E13: =E12*Assumptions!$F$17 -> 719655.84 | F13: =F12*Assumptions!$F$17 -> 684499.25 | G13: =G12*Assumptions!$F$17 -> 646793.82 | H13: =H12*Assumptions!$F$17 -> 606354.74 | I13: =I12*Assumptions!$F$17 -> 562983.83 | J13: =J12*Assumptions!$F$17 -> 516468.52 | ... L13: =L12*Assumptions!$F$17 -> 413076.34
A14: Payment | C14: =IF(C12>0,MIN($B$11,C12+C13),0) -> 1204574.2 | D14: =IF(D12>0,MIN($B$11,D12+D13),0) -> 1204574.2 | E14: =IF(E12>0,MIN($B$11,E12+E13),0) -> 1204574.2 | F14: =IF(F12>0,MIN($B$11,F12+F13),0) -> 1204574.2 | G14: =IF(G12>0,MIN($B$11,G12+G13),0) -> 1204574.2 | H14: =IF(H12>0,MIN($B$11,H12+H13),0) -> 1204574.2 | I14: =IF(I12>0,MIN($B$11,I12+I13),0) -> 1204574.2 | J14: =IF(J12>0,MIN($B$11,J12+J13),0) -> 1204574.2 | ... L14: =IF(L12>0,MIN($B$11,L12+L13),0) -> 1204574.2
A15: Principal | C15: =C14-C13 -> 421574.23 | D15: =D14-D13 -> 452138.36 | E15: =E14-E13 -> 484918.39 | F15: =F14-F13 -> 520074.98 | G15: =G14-G13 -> 557780.41 | H15: =H14-H13 -> 598219.49 | I15: =I14-I13 -> 641590.4 | J15: =J14-J13 -> 688105.71 | ... L15: =L14-L13 -> 791497.89
A16: Ending balance | C16: =C12-C15 -> 10378426 | D16: =D12-D15 -> 9926287.4 | E16: =E12-E15 -> 9441369 | F16: =F12-F15 -> 8921294 | G16: =G12-G15 -> 8363513.6 | H16: =H12-H15 -> 7765294.1 | I16: =I12-I15 -> 7123703.7 | J16: =J12-J15 -> 6435598 | ... L16: =L12-L15 -> 4906106.8
A17: Market value (year end) | C17: =IF(C$5>=$B$8,$B$9*(1-Assumptions!$F$63)^(C$5-$B$8+1),0) -> 12825000 | D17: =IF(D$5>=$B$8,$B$9*(1-Assumptions!$F$63)^(D$5-$B$8+1),0) -> 12183750 | E17: =IF(E$5>=$B$8,$B$9*(1-Assumptions!$F$63)^(E$5-$B$8+1),0) -> 11574562 | F17: =IF(F$5>=$B$8,$B$9*(1-Assumptions!$F$63)^(F$5-$B$8+1),0) -> 10995834 | G17: =IF(G$5>=$B$8,$B$9*(1-Assumptions!$F$63)^(G$5-$B$8+1),0) -> 10446043 | H17: =IF(H$5>=$B$8,$B$9*(1-Assumptions!$F$63)^(H$5-$B$8+1),0) -> 9923740.5 | I17: =IF(I$5>=$B$8,$B$9*(1-Assumptions!$F$63)^(I$5-$B$8+1),0) -> 9427553.5 | J17: =IF(J$5>=$B$8,$B$9*(1-Assumptions!$F$63)^(J$5-$B$8+1),0) -> 8956175.8 | ... L17: =IF(L$5>=$B$8,$B$9*(1-Assumptions!$F$63)^(L$5-$B$8+1),0) -> 8082948.7
A19: Aircraft #2
A20: Purchase year | B20: =2027+COUNTIF('Fleet Plan'!$C$9:$L$9,"<2") -> 2030
A21: Price paid | B21: =IF($B$20>2036,0,Assumptions!$F$7*(1+Assumptions!$F$8)^($B$20-2027)) -> 13500000
A22: Loan | B22: =$B$21*Assumptions!$F$16 -> 10800000
A23: Annual payment | B23: =IF($B$22=0,0,PMT(Assumptions!$F$17,Assumptions!$F$18,-$B$22)) -> 1204574.2
A24: Beginning balance | C24: =IF(C$5=$B$20,$B$22,IF(C$5>$B$20,0,0)) -> 0 | D24: =IF(D$5=$B$20,$B$22,IF(D$5>$B$20,C28,0)) -> 0 | E24: =IF(E$5=$B$20,$B$22,IF(E$5>$B$20,D28,0)) -> 0 | F24: =IF(F$5=$B$20,$B$22,IF(F$5>$B$20,E28,0)) -> 10800000 | G24: =IF(G$5=$B$20,$B$22,IF(G$5>$B$20,F28,0)) -> 10378426 | H24: =IF(H$5=$B$20,$B$22,IF(H$5>$B$20,G28,0)) -> 9926287.4 | I24: =IF(I$5=$B$20,$B$22,IF(I$5>$B$20,H28,0)) -> 9441369 | J24: =IF(J$5=$B$20,$B$22,IF(J$5>$B$20,I28,0)) -> 8921294 | K24: =IF(K$5=$B$20,$B$22,IF(K$5>$B$20,J28,0)) -> 8363513.6 | L24: =IF(L$5=$B$20,$B$22,IF(L$5>$B$20,K28,0)) -> 7765294.1
A25: Interest | C25: =C24*Assumptions!$F$17 -> 0 | D25: =D24*Assumptions!$F$17 -> 0 | E25: =E24*Assumptions!$F$17 -> 0 | F25: =F24*Assumptions!$F$17 -> 783000 | G25: =G24*Assumptions!$F$17 -> 752435.87 | H25: =H24*Assumptions!$F$17 -> 719655.84 | I25: =I24*Assumptions!$F$17 -> 684499.25 | J25: =J24*Assumptions!$F$17 -> 646793.82 | ... L25: =L24*Assumptions!$F$17 -> 562983.83
A26: Payment | C26: =IF(C24>0,MIN($B$23,C24+C25),0) -> 0 | D26: =IF(D24>0,MIN($B$23,D24+D25),0) -> 0 | E26: =IF(E24>0,MIN($B$23,E24+E25),0) -> 0 | F26: =IF(F24>0,MIN($B$23,F24+F25),0) -> 1204574.2 | G26: =IF(G24>0,MIN($B$23,G24+G25),0) -> 1204574.2 | H26: =IF(H24>0,MIN($B$23,H24+H25),0) -> 1204574.2 | I26: =IF(I24>0,MIN($B$23,I24+I25),0) -> 1204574.2 | J26: =IF(J24>0,MIN($B$23,J24+J25),0) -> 1204574.2 | ... L26: =IF(L24>0,MIN($B$23,L24+L25),0) -> 1204574.2
A27: Principal | C27: =C26-C25 -> 0 | D27: =D26-D25 -> 0 | E27: =E26-E25 -> 0 | F27: =F26-F25 -> 421574.23 | G27: =G26-G25 -> 452138.36 | H27: =H26-H25 -> 484918.39 | I27: =I26-I25 -> 520074.98 | J27: =J26-J25 -> 557780.41 | ... L27: =L26-L25 -> 641590.4
A28: Ending balance | C28: =C24-C27 -> 0 | D28: =D24-D27 -> 0 | E28: =E24-E27 -> 0 | F28: =F24-F27 -> 10378426 | G28: =G24-G27 -> 9926287.4 | H28: =H24-H27 -> 9441369 | I28: =I24-I27 -> 8921294 | J28: =J24-J27 -> 8363513.6 | ... L28: =L24-L27 -> 7123703.7
A29: Market value (year end) | C29: =IF(C$5>=$B$20,$B$21*(1-Assumptions!$F$63)^(C$5-$B$20+1),0) -> 0 | D29: =IF(D$5>=$B$20,$B$21*(1-Assumptions!$F$63)^(D$5-$B$20+1),0) -> 0 | E29: =IF(E$5>=$B$20,$B$21*(1-Assumptions!$F$63)^(E$5-$B$20+1),0) -> 0 | F29: =IF(F$5>=$B$20,$B$21*(1-Assumptions!$F$63)^(F$5-$B$20+1),0) -> 12825000 | G29: =IF(G$5>=$B$20,$B$21*(1-Assumptions!$F$63)^(G$5-$B$20+1),0) -> 12183750 | H29: =IF(H$5>=$B$20,$B$21*(1-Assumptions!$F$63)^(H$5-$B$20+1),0) -> 11574562 | I29: =IF(I$5>=$B$20,$B$21*(1-Assumptions!$F$63)^(I$5-$B$20+1),0) -> 10995834 | J29: =IF(J$5>=$B$20,$B$21*(1-Assumptions!$F$63)^(J$5-$B$20+1),0) -> 10446043 | ... L29: =IF(L$5>=$B$20,$B$21*(1-Assumptions!$F$63)^(L$5-$B$20+1),0) -> 9427553.5
A31: Aircraft #3
A32: Purchase year | B32: =2027+COUNTIF('Fleet Plan'!$C$9:$L$9,"<3") -> 2033
A33: Price paid | B33: =IF($B$32>2036,0,Assumptions!$F$7*(1+Assumptions!$F$8)^($B$32-2027)) -> 13500000
A34: Loan | B34: =$B$33*Assumptions!$F$16 -> 10800000
A35: Annual payment | B35: =IF($B$34=0,0,PMT(Assumptions!$F$17,Assumptions!$F$18,-$B$34)) -> 1204574.2
A36: Beginning balance | C36: =IF(C$5=$B$32,$B$34,IF(C$5>$B$32,0,0)) -> 0 | D36: =IF(D$5=$B$32,$B$34,IF(D$5>$B$32,C40,0)) -> 0 | E36: =IF(E$5=$B$32,$B$34,IF(E$5>$B$32,D40,0)) -> 0 | F36: =IF(F$5=$B$32,$B$34,IF(F$5>$B$32,E40,0)) -> 0 | G36: =IF(G$5=$B$32,$B$34,IF(G$5>$B$32,F40,0)) -> 0 | H36: =IF(H$5=$B$32,$B$34,IF(H$5>$B$32,G40,0)) -> 0 | I36: =IF(I$5=$B$32,$B$34,IF(I$5>$B$32,H40,0)) -> 10800000 | J36: =IF(J$5=$B$32,$B$34,IF(J$5>$B$32,I40,0)) -> 10378426 | K36: =IF(K$5=$B$32,$B$34,IF(K$5>$B$32,J40,0)) -> 9926287.4 | L36: =IF(L$5=$B$32,$B$34,IF(L$5>$B$32,K40,0)) -> 9441369
A37: Interest | C37: =C36*Assumptions!$F$17 -> 0 | D37: =D36*Assumptions!$F$17 -> 0 | E37: =E36*Assumptions!$F$17 -> 0 | F37: =F36*Assumptions!$F$17 -> 0 | G37: =G36*Assumptions!$F$17 -> 0 | H37: =H36*Assumptions!$F$17 -> 0 | I37: =I36*Assumptions!$F$17 -> 783000 | J37: =J36*Assumptions!$F$17 -> 752435.87 | ... L37: =L36*Assumptions!$F$17 -> 684499.25
A38: Payment | C38: =IF(C36>0,MIN($B$35,C36+C37),0) -> 0 | D38: =IF(D36>0,MIN($B$35,D36+D37),0) -> 0 | E38: =IF(E36>0,MIN($B$35,E36+E37),0) -> 0 | F38: =IF(F36>0,MIN($B$35,F36+F37),0) -> 0 | G38: =IF(G36>0,MIN($B$35,G36+G37),0) -> 0 | H38: =IF(H36>0,MIN($B$35,H36+H37),0) -> 0 | I38: =IF(I36>0,MIN($B$35,I36+I37),0) -> 1204574.2 | J38: =IF(J36>0,MIN($B$35,J36+J37),0) -> 1204574.2 | ... L38: =IF(L36>0,MIN($B$35,L36+L37),0) -> 1204574.2
A39: Principal | C39: =C38-C37 -> 0 | D39: =D38-D37 -> 0 | E39: =E38-E37 -> 0 | F39: =F38-F37 -> 0 | G39: =G38-G37 -> 0 | H39: =H38-H37 -> 0 | I39: =I38-I37 -> 421574.23 | J39: =J38-J37 -> 452138.36 | ... L39: =L38-L37 -> 520074.98
A40: Ending balance | C40: =C36-C39 -> 0 | D40: =D36-D39 -> 0 | E40: =E36-E39 -> 0 | F40: =F36-F39 -> 0 | G40: =G36-G39 -> 0 | H40: =H36-H39 -> 0 | I40: =I36-I39 -> 10378426 | J40: =J36-J39 -> 9926287.4 | ... L40: =L36-L39 -> 8921294
A41: Market value (year end) | C41: =IF(C$5>=$B$32,$B$33*(1-Assumptions!$F$63)^(C$5-$B$32+1),0) -> 0 | D41: =IF(D$5>=$B$32,$B$33*(1-Assumptions!$F$63)^(D$5-$B$32+1),0) -> 0 | E41: =IF(E$5>=$B$32,$B$33*(1-Assumptions!$F$63)^(E$5-$B$32+1),0) -> 0 | F41: =IF(F$5>=$B$32,$B$33*(1-Assumptions!$F$63)^(F$5-$B$32+1),0) -> 0 | G41: =IF(G$5>=$B$32,$B$33*(1-Assumptions!$F$63)^(G$5-$B$32+1),0) -> 0 | H41: =IF(H$5>=$B$32,$B$33*(1-Assumptions!$F$63)^(H$5-$B$32+1),0) -> 0 | I41: =IF(I$5>=$B$32,$B$33*(1-Assumptions!$F$63)^(I$5-$B$32+1),0) -> 12825000 | J41: =IF(J$5>=$B$32,$B$33*(1-Assumptions!$F$63)^(J$5-$B$32+1),0) -> 12183750 | ... L41: =IF(L$5>=$B$32,$B$33*(1-Assumptions!$F$63)^(L$5-$B$32+1),0) -> 10995834
A43: Aircraft #4
A44: Purchase year | B44: =2027+COUNTIF('Fleet Plan'!$C$9:$L$9,"<4") -> 2037
A45: Price paid | B45: =IF($B$44>2036,0,Assumptions!$F$7*(1+Assumptions!$F$8)^($B$44-2027)) -> 0
...

Sheet Exit
A1: Exit valuation (Live scenario)
A2: Fleet sold at market, debt repaid, management platform sold at an EBITDA multiple.
A4: Item | C4: Value | D4: Note
A5: Exit year | C5: =Assumptions!$F$60 -> 2036
A6: Fleet market value | C6: =INDEX(Forecast!$C$59:$L$59,MATCH(Assumptions!$F$60,Forecast!$C$5:$L$5,0)) -> 28506337 | D6: Debt Schedule, year-end market value
A7: Less selling costs | C7: =-C6*Assumptions!$F$62 -> -570126.73
A8: Third-party management margin in exit year | C8: =INDEX(Forecast!$C$22:$L$22,MATCH(Assumptions!$F$60,Forecast!$C$5:$L$5,0)) -> 3000978.3 | D8: Recurring platform earnings
A9: Platform value (margin x multiple) | C9: =C8*Assumptions!$F$61 -> 18005870 | D9: Buyers pay for managed fleet and certificate
A10: Enterprise value | C10: =C6+C7+C9 -> 45942080
A11: Less debt outstanding | C11: =-INDEX(Forecast!$C$60:$L$60,MATCH(Assumptions!$F$60,Forecast!$C$5:$L$5,0)) -> -20951105
A12: Plus cash on hand | C12: =INDEX(Forecast!$C$55:$L$55,MATCH(Assumptions!$F$60,Forecast!$C$5:$L$5,0)) -> 6703368
A13: Equity value at exit (before tax) | C13: =SUM(C10:C12) -> 31694343
A14: Less illustrative tax on depreciation recapture | C14: =0 -> 0 | D14: Set to zero here: depends on Henry's tax position. See Forecast memo and talk to a CPA.
A15: Net exit proceeds to owners | C15: =C13+C14 -> 31694343
A17: Total owner equity contributed | C17: =SUMPRODUCT((Forecast!$C$5:$L$5<=Assumptions!$F$60)*Forecast!$C$54:$L$54) -> 17667996
A18: Multiple on invested equity (MOIC) | C18: =IF(C17=0,0,C15/C17) -> 1.7938844
A19: Equity IRR | C19: =IFERROR(IRR(Forecast!$C$72:$L$72),"n/a") -> 0.094001978 | D19: Ignores the tax memo; including usable tax losses would raise it.
A20: Peak cumulative equity | C20: =MAX(Forecast!$C$56:$L$56) -> 17667996 | D20: Cash Henry and partners must be able to fund
